<?xml version="1.0"?>
<!--
  Simple Humanoid Robot Model for Gazebo Simulation

  This URDF defines a simplified humanoid robot with basic body parts
  including head, torso, arms, and legs for simulation in Gazebo.
-->
<robot name="simple_humanoid">

  <!-- Materials -->
  <material name="blue">
    <color rgba="0.0 0.0 1.0 1.0"/>
  </material>
  <material name="black">
    <color rgba="0.0 0.0 0.0 1.0"/>
  </material>
  <material name="white">
    <color rgba="1.0 1.0 1.0 1.0"/>
  </material>
  <material name="red">
    <color rgba="1.0 0.0 0.0 1.0"/>
  </material>
  <material name="green">
    <color rgba="0.0 1.0 0.0 1.0"/>
  </material>
  <material name="gray">
    <color rgba="0.5 0.5 0.5 1.0"/>
  </material>

  <!-- Base Footprint -->
  <link name="base_footprint">
    <visual>
      <geometry>
        <sphere radius="0.01"/>
      </geometry>
      <material name="red"/>
    </visual>
    <collision>
      <geometry>
        <sphere radius="0.01"/>
      </geometry>
    </collision>
    <inertial>
      <mass value="0.0001"/>
      <inertia ixx="0.0001" ixy="0.0" ixz="0.0" iyy="0.0001" iyz="0.0" izz="0.0001"/>
    </inertial>
  </link>

  <!-- Base Link -->
  <joint name="base_joint" type="fixed">
    <parent link="base_footprint"/>
    <child link="base_link"/>
    <origin xyz="0 0 0.05" rpy="0 0 0"/>
  </joint>

  <link name="base_link">
    <visual>
      <geometry>
        <cylinder length="0.1" radius="0.15"/>
      </geometry>
      <material name="blue"/>
    </visual>
    <collision>
      <geometry>
        <cylinder length="0.1" radius="0.15"/>
      </geometry>
    </collision>
    <inertial>
      <mass value="5.0"/>
      <inertia ixx="0.027" ixy="0.0" ixz="0.0" iyy="0.027" iyz="0.0" izz="0.05"/>
    </inertial>
  </link>

  <!-- Torso -->
  <joint name="torso_joint" type="fixed">
    <parent link="base_link"/>
    <child link="torso"/>
    <origin xyz="0 0 0.25" rpy="0 0 0"/>
  </joint>

  <link name="torso">
    <visual>
      <geometry>
        <box size="0.3 0.2 0.5"/>
      </geometry>
      <material name="gray"/>
    </visual>
    <collision>
      <geometry>
        <box size="0.3 0.2 0.5"/>
      </geometry>
    </collision>
    <inertial>
      <mass value="10.0"/>
      <inertia ixx="0.2083" ixy="0.0" ixz="0.0" iyy="0.325" iyz="0.0" izz="0.325"/>
    </inertial>
  </link>

  <!-- Head -->
  <joint name="neck_joint" type="revolute">
    <parent link="torso"/>
    <child link="head"/>
    <origin xyz="0 0 0.35" rpy="0 0 0"/>
    <axis xyz="0 0 1"/>
    <limit lower="-1.57" upper="1.57" effort="10.0" velocity="1.0"/>
  </joint>

  <link name="head">
    <visual>
      <geometry>
        <sphere radius="0.1"/>
      </geometry>
      <material name="white"/>
    </visual>
    <collision>
      <geometry>
        <sphere radius="0.1"/>
      </geometry>
    </collision>
    <inertial>
      <mass value="2.0"/>
      <inertia ixx="0.008" ixy="0.0" ixz="0.0" iyy="0.008" iyz="0.0" izz="0.008"/>
    </inertial>
  </link>

  <!-- Left Arm -->
  <joint name="left_shoulder_joint" type="revolute">
    <parent link="torso"/>
    <child link="left_upper_arm"/>
    <origin xyz="0.2 0.1 0.1" rpy="0 0 0"/>
    <axis xyz="0 1 0"/>
    <limit lower="-1.57" upper="1.57" effort="10.0" velocity="1.0"/>
  </joint>

  <link name="left_upper_arm">
    <visual>
      <geometry>
        <cylinder length="0.3" radius="0.05"/>
      </geometry>
      <material name="green"/>
    </visual>
    <collision>
      <geometry>
        <cylinder length="0.3" radius="0.05"/>
      </geometry>
    </collision>
    <inertial>
      <mass value="1.0"/>
      <inertia ixx="0.0075" ixy="0.0" ixz="0.0" iyy="0.0075" iyz="0.0" izz="0.00125"/>
    </inertial>
  </link>

  <joint name="left_elbow_joint" type="revolute">
    <parent link="left_upper_arm"/>
    <child link="left_lower_arm"/>
    <origin xyz="0 0 -0.3" rpy="0 0 0"/>
    <axis xyz="0 1 0"/>
    <limit lower="-1.57" upper="1.57" effort="10.0" velocity="1.0"/>
  </joint>

  <link name="left_lower_arm">
    <visual>
      <geometry>
        <cylinder length="0.3" radius="0.04"/>
      </geometry>
      <material name="green"/>
    </visual>
    <collision>
      <geometry>
        <cylinder length="0.3" radius="0.04"/>
      </geometry>
    </collision>
    <inertial>
      <mass value="0.8"/>
      <inertia ixx="0.006" ixy="0.0" ixz="0.0" iyy="0.006" iyz="0.0" izz="0.001"/>
    </inertial>
  </link>

  <!-- Right Arm -->
  <joint name="right_shoulder_joint" type="revolute">
    <parent link="torso"/>
    <child link="right_upper_arm"/>
    <origin xyz="0.2 -0.1 0.1" rpy="0 0 0"/>
    <axis xyz="0 1 0"/>
    <limit lower="-1.57" upper="1.57" effort="10.0" velocity="1.0"/>
  </joint>

  <link name="right_upper_arm">
    <visual>
      <geometry>
        <cylinder length="0.3" radius="0.05"/>
      </geometry>
      <material name="green"/>
    </visual>
    <collision>
      <geometry>
        <cylinder length="0.3" radius="0.05"/>
      </geometry>
    </collision>
    <inertial>
      <mass value="1.0"/>
      <inertia ixx="0.0075" ixy="0.0" ixz="0.0" iyy="0.0075" iyz="0.0" izz="0.00125"/>
    </inertial>
  </link>

  <joint name="right_elbow_joint" type="revolute">
    <parent link="right_upper_arm"/>
    <child link="right_lower_arm"/>
    <origin xyz="0 0 -0.3" rpy="0 0 0"/>
    <axis xyz="0 1 0"/>
    <limit lower="-1.57" upper="1.57" effort="10.0" velocity="1.0"/>
  </joint>

  <link name="right_lower_arm">
    <visual>
      <geometry>
        <cylinder length="0.3" radius="0.04"/>
      </geometry>
      <material name="green"/>
    </visual>
    <collision>
      <geometry>
        <cylinder length="0.3" radius="0.04"/>
      </geometry>
    </collision>
    <inertial>
      <mass value="0.8"/>
      <inertia ixx="0.006" ixy="0.0" ixz="0.0" iyy="0.006" iyz="0.0" izz="0.001"/>
    </inertial>
  </link>

  <!-- Left Leg -->
  <joint name="left_hip_joint" type="revolute">
    <parent link="base_link"/>
    <child link="left_thigh"/>
    <origin xyz="-0.1 0.1 -0.05" rpy="0 0 0"/>
    <axis xyz="0 1 0"/>
    <limit lower="-1.57" upper="1.57" effort="20.0" velocity="1.0"/>
  </joint>

  <link name="left_thigh">
    <visual>
      <geometry>
        <cylinder length="0.4" radius="0.06"/>
      </geometry>
      <material name="black"/>
    </visual>
    <collision>
      <geometry>
        <cylinder length="0.4" radius="0.06"/>
      </geometry>
    </collision>
    <inertial>
      <mass value="2.0"/>
      <inertia ixx="0.028" ixy="0.0" ixz="0.0" iyy="0.028" iyz="0.0" izz="0.0036"/>
    </inertial>
  </link>

  <joint name="left_knee_joint" type="revolute">
    <parent link="left_thigh"/>
    <child link="left_shin"/>
    <origin xyz="0 0 -0.4" rpy="0 0 0"/>
    <axis xyz="0 1 0"/>
    <limit lower="-1.57" upper="1.57" effort="20.0" velocity="1.0"/>
  </joint>

  <link name="left_shin">
    <visual>
      <geometry>
        <cylinder length="0.4" radius="0.05"/>
      </geometry>
      <material name="black"/>
    </visual>
    <collision>
      <geometry>
        <cylinder length="0.4" radius="0.05"/>
      </geometry>
    </collision>
    <inertial>
      <mass value="1.5"/>
      <inertia ixx="0.02" ixy="0.0" ixz="0.0" iyy="0.02" iyz="0.0" izz="0.003125"/>
    </inertial>
  </link>

  <joint name="left_ankle_joint" type="revolute">
    <parent link="left_shin"/>
    <child link="left_foot"/>
    <origin xyz="0 0 -0.4" rpy="0 0 0"/>
    <axis xyz="0 0 1"/>
    <limit lower="-0.5" upper="0.5" effort="10.0" velocity="1.0"/>
  </joint>

  <link name="left_foot">
    <visual>
      <geometry>
        <box size="0.2 0.1 0.05"/>
      </geometry>
      <material name="white"/>
    </visual>
    <collision>
      <geometry>
        <box size="0.2 0.1 0.05"/>
      </geometry>
    </collision>
    <inertial>
      <mass value="0.5"/>
      <inertia ixx="0.00046875" ixy="0.0" ixz="0.0" iyy="0.00125" iyz="0.0" izz="0.00166667"/>
    </inertial>
  </link>

  <!-- Right Leg -->
  <joint name="right_hip_joint" type="revolute">
    <parent link="base_link"/>
    <child link="right_thigh"/>
    <origin xyz="-0.1 -0.1 -0.05" rpy="0 0 0"/>
    <axis xyz="0 1 0"/>
    <limit lower="-1.57" upper="1.57" effort="20.0" velocity="1.0"/>
  </joint>

  <link name="right_thigh">
    <visual>
      <geometry>
        <cylinder length="0.4" radius="0.06"/>
      </geometry>
      <material name="black"/>
    </visual>
    <collision>
      <geometry>
        <cylinder length="0.4" radius="0.06"/>
      </geometry>
    </collision>
    <inertial>
      <mass value="2.0"/>
      <inertia ixx="0.028" ixy="0.0" ixz="0.0" iyy="0.028" iyz="0.0" izz="0.0036"/>
    </inertial>
  </link>

  <joint name="right_knee_joint" type="revolute">
    <parent link="right_thigh"/>
    <child link="right_shin"/>
    <origin xyz="0 0 -0.4" rpy="0 0 0"/>
    <axis xyz="0 1 0"/>
    <limit lower="-1.57" upper="1.57" effort="20.0" velocity="1.0"/>
  </joint>

  <link name="right_shin">
    <visual>
      <geometry>
        <cylinder length="0.4" radius="0.05"/>
      </geometry>
      <material name="black"/>
    </visual>
    <collision>
      <geometry>
        <cylinder length="0.4" radius="0.05"/>
      </geometry>
    </collision>
    <inertial>
      <mass value="1.5"/>
      <inertia ixx="0.02" ixy="0.0" ixz="0.0" iyy="0.02" iyz="0.0" izz="0.003125"/>
    </inertial>
  </link>

  <joint name="right_ankle_joint" type="revolute">
    <parent link="right_shin"/>
    <child link="right_foot"/>
    <origin xyz="0 0 -0.4" rpy="0 0 0"/>
    <axis xyz="0 0 1"/>
    <limit lower="-0.5" upper="0.5" effort="10.0" velocity="1.0"/>
  </joint>

  <link name="right_foot">
    <visual>
      <geometry>
        <box size="0.2 0.1 0.05"/>
      </geometry>
      <material name="white"/>
    </visual>
    <collision>
      <geometry>
        <box size="0.2 0.1 0.05"/>
      </geometry>
    </collision>
    <inertial>
      <mass value="0.5"/>
      <inertia ixx="0.00046875" ixy="0.0" ixz="0.0" iyy="0.00125" iyz="0.0" izz="0.00166667"/>
    </inertial>
  </link>

  <!-- Gazebo-specific elements -->
  <gazebo reference="base_link">
    <material>Gazebo/Blue</material>
    <mu1>0.2</mu1>
    <mu2>0.2</mu2>
    <kp>1000000.0</kp>
    <kd>1.0</kd>
  </gazebo>

  <gazebo reference="torso">
    <material>Gazebo/Gray</material>
    <mu1>0.2</mu1>
    <mu2>0.2</mu2>
    <kp>1000000.0</kp>
    <kd>1.0</kd>
  </gazebo>

  <gazebo reference="head">
    <material>Gazebo/White</material>
    <mu1>0.2</mu1>
    <mu2>0.2</mu2>
    <kp>1000000.0</kp>
    <kd>1.0</kd>
  </gazebo>

  <gazebo reference="left_upper_arm">
    <material>Gazebo/Green</material>
    <mu1>0.2</mu1>
    <mu2>0.2</mu2>
    <kp>1000000.0</kp>
    <kd>1.0</kd>
  </gazebo>

  <gazebo reference="left_lower_arm">
    <material>Gazebo/Green</material>
    <mu1>0.2</mu1>
    <mu2>0.2</mu2>
    <kp>1000000.0</kp>
    <kd>1.0</kd>
  </gazebo>

  <gazebo reference="right_upper_arm">
    <material>Gazebo/Green</material>
    <mu1>0.2</mu1>
    <mu2>0.2</mu2>
    <kp>1000000.0</kp>
    <kd>1.0</kd>
  </gazebo>

  <gazebo reference="right_lower_arm">
    <material>Gazebo/Green</material>
    <mu1>0.2</mu1>
    <mu2>0.2</mu2>
    <kp>1000000.0</kp>
    <kd>1.0</kd>
  </gazebo>

  <gazebo reference="left_thigh">
    <material>Gazebo/Black</material>
    <mu1>0.2</mu1>
    <mu2>0.2</mu2>
    <kp>1000000.0</kp>
    <kd>1.0</kd>
  </gazebo>

  <gazebo reference="left_shin">
    <material>Gazebo/Black</material>
    <mu1>0.2</mu1>
    <mu2>0.2</mu2>
    <kp>1000000.0</kp>
    <kd>1.0</kd>
  </gazebo>

  <gazebo reference="left_foot">
    <material>Gazebo/White</material>
    <mu1>0.8</mu1>
    <mu2>0.8</mu2>
    <kp>1000000.0</kp>
    <kd>1.0</kd>
  </gazebo>

  <gazebo reference="right_thigh">
    <material>Gazebo/Black</material>
    <mu1>0.2</mu1>
    <mu2>0.2</mu2>
    <kp>1000000.0</kp>
    <kd>1.0</kd>
  </gazebo>

  <gazebo reference="right_shin">
    <material>Gazebo/Black</material>
    <mu1>0.2</mu1>
    <mu2>0.2</mu2>
    <kp>1000000.0</kp>
    <kd>1.0</kd>
  </gazebo>

  <gazebo reference="right_foot">
    <material>Gazebo/White</material>
    <mu1>0.8</mu1>
    <mu2>0.8</mu2>
    <kp>1000000.0</kp>
    <kd>1.0</kd>
  </gazebo>

  <!-- Gazebo plugin for ROS control -->
  <gazebo>
    <plugin name="gazebo_ros_control" filename="libgazebo_ros_control.so">
      <robotNamespace>/simple_humanoid</robotNamespace>
      <robotSimType>gazebo_ros_control/DefaultRobotHWSim</robotSimType>
    </plugin>
  </gazebo>

</robot>